<?xml version="1.0" encoding="utf-8"?>
<robot name="panda">
    <link name="world"/>
    <joint name="base_link" type="fixed">
      <parent link="world"/>
      <child link="panda_hand"/>
       <origin rpy="0 0 0" xyz="0 0 0"/>
    </joint> 

    <link name="panda_hand">
        <inertial>
            <mass value="0.73"/>
            <origin rpy="0 0 0" xyz="0 0.0015244 0.0275912"/>
            <inertia ixx="0.00278560230025" ixy="0.0" ixz="0.0" iyy="0.000400033405336" iyz="0.0"
                     izz="0.00256378041832"/>
        </inertial>
        <visual>
            <origin rpy="0 0 0" xyz="0 0 0"/>
            <geometry>                
                <box size="0.035 0.19 0.065"/>
            </geometry>
            <material name="">
                <color rgba="1 1 1 1"/>
            </material>
        </visual>
        <collision>
            <origin rpy="0 0 0" xyz="0 0 0.0333"/>
            <geometry>
                <box size="0.035 0.19 0.065"/>
            </geometry>
        </collision>
    </link>
    <link name="panda_leftfinger">
        <inertial>
            <mass value="0.1"/>
            <origin rpy="0 0 0" xyz="0 0.0145644 0.0227941"/>
            <inertia ixx="3.01220925051e-05" ixy="0.0" ixz="0.0" iyy="2.95873808038e-05" iyz="0.0"
                     izz="6.95125211657e-06"/>
        </inertial>
        <visual>
            <origin rpy="0 0 0" xyz="0 0 0"/>
            <geometry>
                <box size="0.02 0.02 0.05"/>
            </geometry>
            <material name="">
                <color rgba="1 1 1 1"/>
            </material>
        </visual>
        <collision>
            <origin rpy="0 0 0" xyz="0 0.01 0.028"/>
            <geometry>
                <box size="0.02 0.02 0.05"/>
            </geometry>
        </collision>
    </link>
    <link name="panda_rightfinger">
        <inertial>
            <mass value="0.1"/>
            <origin rpy="0 0 3.14159265359" xyz="0 0.0145644 0.0227941"/>
            <inertia ixx="3.01220925051e-05" ixy="0.0" ixz="0.0" iyy="2.95873808038e-05" iyz="0.0"
                     izz="6.95125211657e-06"/>
        </inertial>
        <visual>
            <origin rpy="0 0 3.14159265359" xyz="0 0 0"/>
            <geometry>
                <box size="0.02 0.02 0.05"/>
            </geometry>
            <material name="">
                <color rgba="1 1 1 1"/>
            </material>
        </visual>
        <collision>
            <origin rpy="0 0 3.14159265359" xyz="0 -0.01 0.028"/>
            <geometry>
                <box size="0.02 0.02 0.05"/>
            </geometry>
        </collision>
    </link>
    <joint name="panda_finger_joint1" type="prismatic">
        <parent link="panda_hand"/>
        <child link="panda_leftfinger"/>
        <origin rpy="0 0 0" xyz="0 0 0.0584"/>
        <axis xyz="0 1 0"/>
        <limit effort="20" lower="-0.001" upper="0.04" velocity="0.3"/>
    </joint>
    <joint name="panda_finger_joint2" type="prismatic">
        <parent link="panda_hand"/>
        <child link="panda_rightfinger"/>
        <origin rpy="0 0 0" xyz="0 0 0.0584"/>
        <axis xyz="0 -1 0"/>
        <limit effort="20" lower="-0.001" upper="0.04" velocity="0.3"/>
    </joint>
</robot>